Workbook
Name ExerciseList: [1]!ExerciseDropdown[Exercise]
Name ExerciseList: ExerciseDropdown[Exercise]
Name ExerciseList: ExerciseDropdown[Exercise]
Name ExerciseList: ExerciseDropdown[Exercise]
Name ExerciseListSgLong: [1]!ExerciseDropdown[Exercise]
Name ExerciseListSgLong: ExerciseDropdown[Exercise]
Name ExerciseListSgLong: ExerciseDropdown[Exercise]
Name Slicer_Exercise: #N/A
Name Slicer_Exercise: #N/A
Name Slicer_Unit: #N/A
Name Slicer_Unit: #N/A
Name UnitList: [1]!UnitDropdown[#Data]
Name UnitList: UnitDropdown[]
Name UnitList: UnitDropdown[]
Name UnitList: UnitDropdown[]

Sheet Calendar
A1: 🏋 Gym Attendance Calendar | N1: January | O1: 2026
N2: February | O2: 2027
A3: Year: | B3: 2026 | D3: Month: | E3: August | N3: March | O3: 2028
A4: =TEXT(Control!$A$35,"mmmm yyyy") -> August 2026 | N4: April | O4: 2029
N5: May
A6: Total Session: | B6: =COUNTIF(Control!D33:D1494,"Gym") -> 20 | D6: Gym Days: | E6: =COUNTIFS(Control!$L$3:$L$1464,">="&Control!$A$35,Control!$L$3:$L$1464,"<"&EDATE(Control!$A$35,1),Control!$N$3:$N$1464,"Gym") -> 0 | N6: June
K7: Testing | N7: July
A8: Sun | B8: Mon | C8: Tue | D8: Wed | E8: Thu | F8: Fri | G8: Sat | N8: August
A9: =IF(MONTH(Control!$A$35-Control!$A$36+0)=Control!$A$34,Control!$A$35-Control!$A$36+0,"") | B9: =IF(MONTH(Control!$A$35-Control!$A$36+1)=Control!$A$34,Control!$A$35-Control!$A$36+1,"") | C9: =IF(MONTH(Control!$A$35-Control!$A$36+2)=Control!$A$34,Control!$A$35-Control!$A$36+2,"") | D9: =IF(MONTH(Control!$A$35-Control!$A$36+3)=Control!$A$34,Control!$A$35-Control!$A$36+3,"") | E9: =IF(MONTH(Control!$A$35-Control!$A$36+4)=Control!$A$34,Control!$A$35-Control!$A$36+4,"") | F9: =IF(MONTH(Control!$A$35-Control!$A$36+5)=Control!$A$34,Control!$A$35-Control!$A$36+5,"") | G9: =IF(MONTH(Control!$A$35-Control!$A$36+6)=Control!$A$34,Control!$A$35-Control!$A$36+6,"") -> 46235 | N9: September
A10: =IF(MONTH(Control!$A$35-Control!$A$36+7)=Control!$A$34,Control!$A$35-Control!$A$36+7,"") -> 46236 | B10: =IF(MONTH(Control!$A$35-Control!$A$36+8)=Control!$A$34,Control!$A$35-Control!$A$36+8,"") -> 46237 | C10: =IF(MONTH(Control!$A$35-Control!$A$36+9)=Control!$A$34,Control!$A$35-Control!$A$36+9,"") -> 46238 | D10: =IF(MONTH(Control!$A$35-Control!$A$36+10)=Control!$A$34,Control!$A$35-Control!$A$36+10,"") -> 46239 | E10: =IF(MONTH(Control!$A$35-Control!$A$36+11)=Control!$A$34,Control!$A$35-Control!$A$36+11,"") -> 46240 | F10: =IF(MONTH(Control!$A$35-Control!$A$36+12)=Control!$A$34,Control!$A$35-Control!$A$36+12,"") -> 46241 | G10: =IF(MONTH(Control!$A$35-Control!$A$36+13)=Control!$A$34,Control!$A$35-Control!$A$36+13,"") -> 46242 | N10: October
A11: =IF(MONTH(Control!$A$35-Control!$A$36+14)=Control!$A$34,Control!$A$35-Control!$A$36+14,"") -> 46243 | B11: =IF(MONTH(Control!$A$35-Control!$A$36+15)=Control!$A$34,Control!$A$35-Control!$A$36+15,"") -> 46244 | C11: =IF(MONTH(Control!$A$35-Control!$A$36+16)=Control!$A$34,Control!$A$35-Control!$A$36+16,"") -> 46245 | D11: =IF(MONTH(Control!$A$35-Control!$A$36+17)=Control!$A$34,Control!$A$35-Control!$A$36+17,"") -> 46246 | E11: =IF(MONTH(Control!$A$35-Control!$A$36+18)=Control!$A$34,Control!$A$35-Control!$A$36+18,"") -> 46247 | F11: =IF(MONTH(Control!$A$35-Control!$A$36+19)=Control!$A$34,Control!$A$35-Control!$A$36+19,"") -> 46248 | G11: =IF(MONTH(Control!$A$35-Control!$A$36+20)=Control!$A$34,Control!$A$35-Control!$A$36+20,"") -> 46249 | N11: November
A12: =IF(MONTH(Control!$A$35-Control!$A$36+21)=Control!$A$34,Control!$A$35-Control!$A$36+21,"") -> 46250 | B12: =IF(MONTH(Control!$A$35-Control!$A$36+22)=Control!$A$34,Control!$A$35-Control!$A$36+22,"") -> 46251 | C12: =IF(MONTH(Control!$A$35-Control!$A$36+23)=Control!$A$34,Control!$A$35-Control!$A$36+23,"") -> 46252 | D12: =IF(MONTH(Control!$A$35-Control!$A$36+24)=Control!$A$34,Control!$A$35-Control!$A$36+24,"") -> 46253 | E12: =IF(MONTH(Control!$A$35-Control!$A$36+25)=Control!$A$34,Control!$A$35-Control!$A$36+25,"") -> 46254 | F12: =IF(MONTH(Control!$A$35-Control!$A$36+26)=Control!$A$34,Control!$A$35-Control!$A$36+26,"") -> 46255 | G12: =IF(MONTH(Control!$A$35-Control!$A$36+27)=Control!$A$34,Control!$A$35-Control!$A$36+27,"") -> 46256 | N12: December
A13: =IF(MONTH(Control!$A$35-Control!$A$36+28)=Control!$A$34,Control!$A$35-Control!$A$36+28,"") -> 46257 | B13: =IF(MONTH(Control!$A$35-Control!$A$36+29)=Control!$A$34,Control!$A$35-Control!$A$36+29,"") -> 46258 | C13: =IF(MONTH(Control!$A$35-Control!$A$36+30)=Control!$A$34,Control!$A$35-Control!$A$36+30,"") -> 46259 | D13: =IF(MONTH(Control!$A$35-Control!$A$36+31)=Control!$A$34,Control!$A$35-Control!$A$36+31,"") -> 46260 | E13: =IF(MONTH(Control!$A$35-Control!$A$36+32)=Control!$A$34,Control!$A$35-Control!$A$36+32,"") -> 46261 | F13: =IF(MONTH(Control!$A$35-Control!$A$36+33)=Control!$A$34,Control!$A$35-Control!$A$36+33,"") -> 46262 | G13: =IF(MONTH(Control!$A$35-Control!$A$36+34)=Control!$A$34,Control!$A$35-Control!$A$36+34,"") -> 46263
A14: =IF(MONTH(Control!$A$35-Control!$A$36+35)=Control!$A$34,Control!$A$35-Control!$A$36+35,"") -> 46264 | B14: =IF(MONTH(Control!$A$35-Control!$A$36+36)=Control!$A$34,Control!$A$35-Control!$A$36+36,"") -> 46265 | C14: =IF(MONTH(Control!$A$35-Control!$A$36+37)=Control!$A$34,Control!$A$35-Control!$A$36+37,"") | D14: =IF(MONTH(Control!$A$35-Control!$A$36+38)=Control!$A$34,Control!$A$35-Control!$A$36+38,"") | E14: =IF(MONTH(Control!$A$35-Control!$A$36+39)=Control!$A$34,Control!$A$35-Control!$A$36+39,"") | F14: =IF(MONTH(Control!$A$35-Control!$A$36+40)=Control!$A$34,Control!$A$35-Control!$A$36+40,"") | G14: =IF(MONTH(Control!$A$35-Control!$A$36+41)=Control!$A$34,Control!$A$35-Control!$A$36+41,"")
A16: Legend:
B17: Gym day
B18: Today

Sheet TAR Gym Log
A1: Date (DAY) | B1: Display Date | C1: Exercise | D1: Weight Value | E1: Unit | F1: Reps | G1: Sets | H1: Load | I1: Volumn | J1: Notes
A2: 46213 | B2: 46213 | C2: Chest Press | D2: 90 | E2: lbs | F2: 10 | G2: 2 | H2: =IFERROR(log_5[[#This Row],[Reps]]*log_5[[#This Row],[Sets]],"") -> 20 | I2: =IFERROR(log_5[[#This Row],[Weight Value]]*log_5[[#This Row],[Reps]]*log_5[[#This Row],[Sets]],"") -> 1800 | J2: new machine more wider movement harder
A3: 46213 | B3: 46213 | C3: Chest Press | D3: 90 | E3: lbs | F3: 7 | G3: 1 | H3: =IFERROR(log_5[[#This Row],[Reps]]*log_5[[#This Row],[Sets]],"") -> 7 | I3: =IFERROR(log_5[[#This Row],[Weight Value]]*log_5[[#This Row],[Reps]]*log_5[[#This Row],[Sets]],"") -> 630
A4: 46213 | B4: 46213 | C4: Chest Press | D4: 80 | E4: lbs | F4: 7 | G4: 1 | H4: =IFERROR(log_5[[#This Row],[Reps]]*log_5[[#This Row],[Sets]],"") -> 7 | I4: =IFERROR(log_5[[#This Row],[Weight Value]]*log_5[[#This Row],[Reps]]*log_5[[#This Row],[Sets]],"") -> 560
A5: 46213 | B5: 46213 | C5: Shoulder Press | D5: 50 | E5: lbs | F5: 10 | G5: 1 | H5: =IFERROR(log_5[[#This Row],[Reps]]*log_5[[#This Row],[Sets]],"") -> 10 | I5: =IFERROR(log_5[[#This Row],[Weight Value]]*log_5[[#This Row],[Reps]]*log_5[[#This Row],[Sets]],"") -> 500 | J5: new machine, is not converging, more easier
A6: 46213 | B6: 46213 | C6: Shoulder Press | D6: 60 | E6: lbs | F6: 8 | G6: 3 | H6: =IFERROR(log_5[[#This Row],[Reps]]*log_5[[#This Row],[Sets]],"") -> 24 | I6: =IFERROR(log_5[[#This Row],[Weight Value]]*log_5[[#This Row],[Reps]]*log_5[[#This Row],[Sets]],"") -> 1440
A7: 46213 | B7: 46213 | C7: Pec Fly Backward | D7: 44 | E7: lbs | F7: 8 | G7: 2 | H7: =IFERROR(log_5[[#This Row],[Reps]]*log_5[[#This Row],[Sets]],"") -> 16 | I7: =IFERROR(log_5[[#This Row],[Weight Value]]*log_5[[#This Row],[Reps]]*log_5[[#This Row],[Sets]],"") -> 704
A8: 46213 | B8: 46213 | C8: Pec Fly Backward | D8: 33 | E8: lbs | F8: 8 | G8: 2 | H8: =IFERROR(log_5[[#This Row],[Reps]]*log_5[[#This Row],[Sets]],"") -> 16 | I8: =IFERROR(log_5[[#This Row],[Weight Value]]*log_5[[#This Row],[Reps]]*log_5[[#This Row],[Sets]],"") -> 528
A9: 46213 | B9: 46213 | C9: Lat Pulldown | D9: 90 | E9: lbs | F9: 10 | G9: 3 | H9: =IFERROR(log_5[[#This Row],[Reps]]*log_5[[#This Row],[Sets]],"") -> 30 | I9: =IFERROR(log_5[[#This Row],[Weight Value]]*log_5[[#This Row],[Reps]]*log_5[[#This Row],[Sets]],"") -> 2700
A10: 46213 | B10: 46213 | C10: Lat Pulldown | D10: 90 | E10: lbs | F10: 8 | G10: 1 | H10: =IFERROR(log_5[[#This Row],[Reps]]*log_5[[#This Row],[Sets]],"") -> 8 | I10: =IFERROR(log_5[[#This Row],[Weight Value]]*log_5[[#This Row],[Reps]]*log_5[[#This Row],[Sets]],"") -> 720
A11: 46213 | B11: 46213 | C11: Bicep Curl | D11: 5 | E11: kg | F11: 12 | G11: 4 | H11: =IFERROR(log_5[[#This Row],[Reps]]*log_5[[#This Row],[Sets]],"") -> 48 | I11: =IFERROR(log_5[[#This Row],[Weight Value]]*log_5[[#This Row],[Reps]]*log_5[[#This Row],[Sets]],"") -> 240
A12: 46213 | B12: 46213 | C12: Hammer Curl | D12: 5 | E12: kg | F12: 10 | G12: 4 | H12: =IFERROR(log_5[[#This Row],[Reps]]*log_5[[#This Row],[Sets]],"") -> 40 | I12: =IFERROR(log_5[[#This Row],[Weight Value]]*log_5[[#This Row],[Reps]]*log_5[[#This Row],[Sets]],"") -> 200
A13: 46213 | B13: 46213 | C13: Rope Tricep Pressdown | D13: 35 | E13: lbs | F13: 12 | G13: 2 | H13: =IFERROR(log_5[[#This Row],[Reps]]*log_5[[#This Row],[Sets]],"") -> 24 | I13: =IFERROR(log_5[[#This Row],[Weight Value]]*log_5[[#This Row],[Reps]]*log_5[[#This Row],[Sets]],"") -> 840
A14: 46213 | B14: 46213 | C14: Rope Tricep Pressdown | D14: 45 | E14: lbs | F14: 12 | G14: 1 | H14: =IFERROR(log_5[[#This Row],[Reps]]*log_5[[#This Row],[Sets]],"") -> 12 | I14: =IFERROR(log_5[[#This Row],[Weight Value]]*log_5[[#This Row],[Reps]]*log_5[[#This Row],[Sets]],"") -> 540
A15: 46213 | B15: 46213 | C15: Rope Tricep Pressdown | D15: 45 | E15: lbs | F15: 8 | G15: 1 | H15: =IFERROR(log_5[[#This Row],[Reps]]*log_5[[#This Row],[Sets]],"") -> 8 | I15: =IFERROR(log_5[[#This Row],[Weight Value]]*log_5[[#This Row],[Reps]]*log_5[[#This Row],[Sets]],"") -> 360
A16: 46213 | B16: 46213 | C16: Iso Lateral Row | D16: 10 | E16: kg | F16: 10 | G16: 1 | H16: =IFERROR(log_5[[#This Row],[Reps]]*log_5[[#This Row],[Sets]],"") -> 10 | I16: =IFERROR(log_5[[#This Row],[Weight Value]]*log_5[[#This Row],[Reps]]*log_5[[#This Row],[Sets]],"") -> 100
A17: 46220 | B17: 46220 | C17: Chest Press | D17: 80 | E17: lbs | F17: 10 | G17: 4 | H17: =IFERROR(log_5[[#This Row],[Reps]]*log_5[[#This Row],[Sets]],"") -> 40 | I17: =IFERROR(log_5[[#This Row],[Weight Value]]*log_5[[#This Row],[Reps]]*log_5[[#This Row],[Sets]],"") -> 3200
... A20: 46220 | B20: 46220 | C20: Lat Pulldown | D20: 90 | E20: lbs | F20: 10 | G20: 4 | H20: =IFERROR(log_5[[#This Row],[Reps]]*log_5[[#This Row],[Sets]],"") -> 40 | I20: =IFERROR(log_5[[#This Row],[Weight Value]]*log_5[[#This Row],[Reps]]*log_5[[#This Row],[Sets]],"") -> 3600
A21: 46220 | B21: 46220 | C21: T Bar Row | D21: 10 | E21: kg | F21: 10 | G21: 4 | H21: =IFERROR(log_5[[#This Row],[Reps]]*log_5[[#This Row],[Sets]],"") -> 40 | I21: =IFERROR(log_5[[#This Row],[Weight Value]]*log_5[[#This Row],[Reps]]*log_5[[#This Row],[Sets]],"") -> 400 | J21: Try 2 differrent grip
A22: 46220 | B22: 46220 | C22: Rope Tricep Pressdown | D22: 45 | E22: lbs | F22: 12 | G22: 3 | H22: =IFERROR(log_5[[#This Row],[Reps]]*log_5[[#This Row],[Sets]],"") -> 36 | I22: =IFERROR(log_5[[#This Row],[Weight Value]]*log_5[[#This Row],[Reps]]*log_5[[#This Row],[Sets]],"") -> 1620
A23: 46220 | B23: 46220 | C23: Rope Tricep Pressdown | D23: 45 | E23: lbs | F23: 8 | G23: 1 | H23: =IFERROR(log_5[[#This Row],[Reps]]*log_5[[#This Row],[Sets]],"") -> 8 | I23: =IFERROR(log_5[[#This Row],[Weight Value]]*log_5[[#This Row],[Reps]]*log_5[[#This Row],[Sets]],"") -> 360
A24: 46220 | B24: 46220 | C24: Bicep Curl | D24: 5 | E24: kg | F24: 12 | G24: 4 | H24: =IFERROR(log_5[[#This Row],[Reps]]*log_5[[#This Row],[Sets]],"") -> 48 | I24: =IFERROR(log_5[[#This Row],[Weight Value]]*log_5[[#This Row],[Reps]]*log_5[[#This Row],[Sets]],"") -> 240
A25: 46220 | B25: 46220 | C25: Hammer Curl | D25: 5 | E25: kg | F25: 12 | G25: 3 | H25: =IFERROR(log_5[[#This Row],[Reps]]*log_5[[#This Row],[Sets]],"") -> 36 | I25: =IFERROR(log_5[[#This Row],[Weight Value]]*log_5[[#This Row],[Reps]]*log_5[[#This Row],[Sets]],"") -> 180
A26: 46220 | B26: 46220 | C26: Hammer Curl | D26: 5 | E26: kg | F26: 10 | G26: 1 | H26: =IFERROR(log_5[[#This Row],[Reps]]*log_5[[#This Row],[Sets]],"") -> 10 | I26: =IFERROR(log_5[[#This Row],[Weight Value]]*log_5[[#This Row],[Reps]]*log_5[[#This Row],[Sets]],"") -> 50
A27: 46220 | B27: 46220 | C27: Pec Fly Backward | D27: 33 | E27: lbs | F27: 10 | G27: 1 | H27: =IFERROR(log_5[[#This Row],[Reps]]*log_5[[#This Row],[Sets]],"") -> 10 | I27: =IFERROR(log_5[[#This Row],[Weight Value]]*log_5[[#This Row],[Reps]]*log_5[[#This Row],[Sets]],"") -> 330
A28: 46220 | B28: 46220 | C28: Pec Fly Backward | D28: 33 | E28: lbs | F28: 8 | G28: 1 | H28: =IFERROR(log_5[[#This Row],[Reps]]*log_5[[#This Row],[Sets]],"") -> 8 | I28: =IFERROR(log_5[[#This Row],[Weight Value]]*log_5[[#This Row],[Reps]]*log_5[[#This Row],[Sets]],"") -> 264
A29: 46234 | B29: 46234 | C29: Shoulder Press | D29: 32 | E29: kg | F29: 10 | G29: 1 | H29: =IFERROR(log_5[[#This Row],[Reps]]*log_5[[#This Row],[Sets]],"") -> 10 | I29: =IFERROR(log_5[[#This Row],[Weight Value]]*log_5[[#This Row],[Reps]]*log_5[[#This Row],[Sets]],"") -> 320
A30: 46234 | B30: 46234 | C30: Shoulder Press | D30: 36 | E30: kg | F30: 8 | G30: 1 | H30: =IFERROR(log_5[[#This Row],[Reps]]*log_5[[#This Row],[Sets]],"") -> 8 | I30: =IFERROR(log_5[[#This Row],[Weight Value]]*log_5[[#This Row],[Reps]]*log_5[[#This Row],[Sets]],"") -> 288
A31: 46234 | B31: 46234 | C31: Shoulder Press | D31: 41 | E31: kg | F31: 8 | G31: 2 | H31: =IFERROR(log_5[[#This Row],[Reps]]*log_5[[#This Row],[Sets]],"") -> 16 | I31: =IFERROR(log_5[[#This Row],[Weight Value]]*log_5[[#This Row],[Reps]]*log_5[[#This Row],[Sets]],"") -> 656
A32: 46234 | B32: 46234 | C32: Pec Fly Frontward | D32: 40 | E32: kg | F32: 5 | G32: 2 | H32: =IFERROR(log_5[[#This Row],[Reps]]*log_5[[#This Row],[Sets]],"") -> 10 | I32: =IFERROR(log_5[[#This Row],[Weight Value]]*log_5[[#This Row],[Reps]]*log_5[[#This Row],[Sets]],"") -> 400
A33: 46234 | B33: 46234 | C33: Pec Fly Frontward | D33: 40 | E33: kg | F33: 3 | G33: 1 | H33: =IFERROR(log_5[[#This Row],[Reps]]*log_5[[#This Row],[Sets]],"") -> 3 | I33: =IFERROR(log_5[[#This Row],[Weight Value]]*log_5[[#This Row],[Reps]]*log_5[[#This Row],[Sets]],"") -> 120
... A36: 46234 | B36: 46234 | C36: Pec Fly Backward | D36: 30 | E36: kg | F36: 5 | G36: 1 | H36: =IFERROR(log_5[[#This Row],[Reps]]*log_5[[#This Row],[Sets]],"") -> 5 | I36: =IFERROR(log_5[[#This Row],[Weight Value]]*log_5[[#This Row],[Reps]]*log_5[[#This Row],[Sets]],"") -> 150
A37: 46234 | B37: 46234 | C37: Pec Fly Backward | D37: 25 | E37: kg | F37: 5 | G37: 3 | H37: =IFERROR(log_5[[#This Row],[Reps]]*log_5[[#This Row],[Sets]],"") -> 15 | I37: =IFERROR(log_5[[#This Row],[Weight Value]]*log_5[[#This Row],[Reps]]*log_5[[#This Row],[Sets]],"") -> 375 | J37: Drop weight feel too hard
A38: 46234 | B38: 46234 | C38: Bicep Curl | D38: 7.5 | E38: kg | F38: 8 | G38: 4 | H38: =IFERROR(log_5[[#This Row],[Reps]]*log_5[[#This Row],[Sets]],"") -> 32 | I38: =IFERROR(log_5[[#This Row],[Weight Value]]*log_5[[#This Row],[Reps]]*log_5[[#This Row],[Sets]],"") -> 240
A39: 46234 | B39: 46234 | C39: Hammer Curl | D39: 7.5 | E39: kg | F39: 8 | G39: 4 | H39: =IFERROR(log_5[[#This Row],[Reps]]*log_5[[#This Row],[Sets]],"") -> 32 | I39: =IFERROR(log_5[[#This Row],[Weight Value]]*log_5[[#This Row],[Reps]]*log_5[[#This Row],[Sets]],"") -> 240
A40: 46234 | B40: 46234 | C40: Low Pully | D40: 34 | E40: kg | F40: 8 | G40: 3 | H40: =IFERROR(log_5[[#This Row],[Reps]]*log_5[[#This Row],[Sets]],"") -> 24 | I40: =IFERROR(log_5[[#This Row],[Weight Value]]*log_5[[#This Row],[Reps]]*log_5[[#This Row],[Sets]],"") -> 816
A41: 46234 | B41: 46234 | C41: Rope Tricep Pressdown | D41: 30 | E41: kg | F41: 8 | G41: 3 | H41: =IFERROR(log_5[[#This Row],[Reps]]*log_5[[#This Row],[Sets]],"") -> 24 | I41: =IFERROR(log_5[[#This Row],[Weight Value]]*log_5[[#This Row],[Reps]]*log_5[[#This Row],[Sets]],"") -> 720
A42: 46234 | B42: 46234 | C42: Rope Tricep Pressdown | D42: 30 | E42: kg | F42: 6 | G42: 1 | H42: =IFERROR(log_5[[#This Row],[Reps]]*log_5[[#This Row],[Sets]],"") -> 6 | I42: =IFERROR(log_5[[#This Row],[Weight Value]]*log_5[[#This Row],[Reps]]*log_5[[#This Row],[Sets]],"") -> 180

Sheet Sg Long Gym Log
A1: Date (DAY) | B1: Display Date | C1: Exercise | D1: Weight Value | E1: Unit | F1: Reps | G1: Sets | H1: Load | I1: Volumn | J1: Notes
A2: 46228 | B2: 46228 | C2: Chest Press | D2: 50 | E2: kg | F2: 10 | G2: 2 | H2: =IFERROR(log_8[[#This Row],[Reps]]*log_8[[#This Row],[Sets]],"") -> 20 | I2: =IFERROR(log_8[[#This Row],[Weight Value]]*log_8[[#This Row],[Reps]]*log_8[[#This Row],[Sets]],"") -> 1000 | J2: New machine - multi press
A3: 46228 | B3: 46228 | C3: Chest Press | D3: 80 | E3: kg | F3: 10 | G3: 2 | H3: =IFERROR(log_8[[#This Row],[Reps]]*log_8[[#This Row],[Sets]],"") -> 20 | I3: =IFERROR(log_8[[#This Row],[Weight Value]]*log_8[[#This Row],[Reps]]*log_8[[#This Row],[Sets]],"") -> 1600
A4: 46228 | B4: 46228 | C4: Incline Press | D4: 50 | E4: kg | F4: 10 | G4: 1 | H4: =IFERROR(log_8[[#This Row],[Reps]]*log_8[[#This Row],[Sets]],"") -> 10 | I4: =IFERROR(log_8[[#This Row],[Weight Value]]*log_8[[#This Row],[Reps]]*log_8[[#This Row],[Sets]],"") -> 500 | J4: Same machine - multi press, but adjust the seat 125 degree, work like shoulder press
A5: 46228 | B5: 46228 | C5: Incline Press | D5: 55 | E5: kg | F5: 10 | G5: 2 | H5: =IFERROR(log_8[[#This Row],[Reps]]*log_8[[#This Row],[Sets]],"") -> 20 | I5: =IFERROR(log_8[[#This Row],[Weight Value]]*log_8[[#This Row],[Reps]]*log_8[[#This Row],[Sets]],"") -> 1100
A6: 46228 | B6: 46228 | C6: Incline Press | D6: 55 | E6: kg | F6: 8 | G6: 1 | H6: =IFERROR(log_8[[#This Row],[Reps]]*log_8[[#This Row],[Sets]],"") -> 8 | I6: =IFERROR(log_8[[#This Row],[Weight Value]]*log_8[[#This Row],[Reps]]*log_8[[#This Row],[Sets]],"") -> 440
A7: 46228 | B7: 46228 | C7: Rope Tricep Pressdown | D7: 20 | E7: kg | F7: 10 | G7: 1 | H7: =IFERROR(log_8[[#This Row],[Reps]]*log_8[[#This Row],[Sets]],"") -> 10 | I7: =IFERROR(log_8[[#This Row],[Weight Value]]*log_8[[#This Row],[Reps]]*log_8[[#This Row],[Sets]],"") -> 200
A8: 46228 | B8: 46228 | C8: Rope Tricep Pressdown | D8: 25 | E8: kg | F8: 10 | G8: 3 | H8: =IFERROR(log_8[[#This Row],[Reps]]*log_8[[#This Row],[Sets]],"") -> 30 | I8: =IFERROR(log_8[[#This Row],[Weight Value]]*log_8[[#This Row],[Reps]]*log_8[[#This Row],[Sets]],"") -> 750 | J8: Last set come back after pully
A9: 46228 | B9: 46228 | C9: High Pully | D9: 40 | E9: kg | F9: 10 | G9: 2 | H9: =IFERROR(log_8[[#This Row],[Reps]]*log_8[[#This Row],[Sets]],"") -> 20 | I9: =IFERROR(log_8[[#This Row],[Weight Value]]*log_8[[#This Row],[Reps]]*log_8[[#This Row],[Sets]],"") -> 800
A10: 46228 | B10: 46228 | C10: High Pully | D10: 40 | E10: kg | F10: 8 | G10: 2 | H10: =IFERROR(log_8[[#This Row],[Reps]]*log_8[[#This Row],[Sets]],"") -> 16 | I10: =IFERROR(log_8[[#This Row],[Weight Value]]*log_8[[#This Row],[Reps]]*log_8[[#This Row],[Sets]],"") -> 640
A11: 46228 | B11: 46228 | C11: Low Pully | D11: 30 | E11: kg | F11: 10 | G11: 2 | H11: =IFERROR(log_8[[#This Row],[Reps]]*log_8[[#This Row],[Sets]],"") -> 20 | I11: =IFERROR(log_8[[#This Row],[Weight Value]]*log_8[[#This Row],[Reps]]*log_8[[#This Row],[Sets]],"") -> 600 | J11: Row
A12: 46228 | B12: 46228 | C12: Low Pully | D12: 35 | E12: kg | F12: 10 | G12: 2 | H12: =IFERROR(log_8[[#This Row],[Reps]]*log_8[[#This Row],[Sets]],"") -> 20 | I12: =IFERROR(log_8[[#This Row],[Weight Value]]*log_8[[#This Row],[Reps]]*log_8[[#This Row],[Sets]],"") -> 700
A13: 46228 | B13: 46228 | C13: Bicep Curl | D13: 7.5 | E13: kg | F13: 8 | G13: 2 | H13: =IFERROR(log_8[[#This Row],[Reps]]*log_8[[#This Row],[Sets]],"") -> 16 | I13: =IFERROR(log_8[[#This Row],[Weight Value]]*log_8[[#This Row],[Reps]]*log_8[[#This Row],[Sets]],"") -> 120
A14: 46228 | B14: 46228 | C14: Bicep Curl | D14: 7.5 | E14: kg | F14: 5 | G14: 2 | H14: =IFERROR(log_8[[#This Row],[Reps]]*log_8[[#This Row],[Sets]],"") -> 10 | I14: =IFERROR(log_8[[#This Row],[Weight Value]]*log_8[[#This Row],[Reps]]*log_8[[#This Row],[Sets]],"") -> 75
A15: 46228 | B15: 46228 | C15: Hammer Curl | D15: 7.5 | E15: kg | F15: 7 | G15: 1 | H15: =IFERROR(log_8[[#This Row],[Reps]]*log_8[[#This Row],[Sets]],"") -> 7 | I15: =IFERROR(log_8[[#This Row],[Weight Value]]*log_8[[#This Row],[Reps]]*log_8[[#This Row],[Sets]],"") -> 52.5
A16: 46228 | B16: 46228 | C16: Hammer Curl | D16: 7.5 | E16: kg | F16: 5 | G16: 3 | H16: =IFERROR(log_8[[#This Row],[Reps]]*log_8[[#This Row],[Sets]],"") -> 15 | I16: =IFERROR(log_8[[#This Row],[Weight Value]]*log_8[[#This Row],[Reps]]*log_8[[#This Row],[Sets]],"") -> 112.5
A17: 46228 | B17: 46228 | C17: Pec Fly Backward | D17: 20 | E17: kg | F17: 10 | G17: 1 | H17: =IFERROR(log_8[[#This Row],[Reps]]*log_8[[#This Row],[Sets]],"") -> 10 | I17: =IFERROR(log_8[[#This Row],[Weight Value]]*log_8[[#This Row],[Reps]]*log_8[[#This Row],[Sets]],"") -> 200
A18: 46228 | B18: 46228 | C18: Pec Fly Backward | D18: 25 | E18: kg | F18: 8 | G18: 3 | H18: =IFERROR(log_8[[#This Row],[Reps]]*log_8[[#This Row],[Sets]],"") -> 24 | I18: =IFERROR(log_8[[#This Row],[Weight Value]]*log_8[[#This Row],[Reps]]*log_8[[#This Row],[Sets]],"") -> 600
A19: 46228 | B19: 46228 | C19: Pec Fly Frontward | D19: 35 | E19: kg | F19: 7 | G19: 1 | H19: =IFERROR(log_8[[#This Row],[Reps]]*log_8[[#This Row],[Sets]],"") -> 7 | I19: =IFERROR(log_8[[#This Row],[Weight Value]]*log_8[[#This Row],[Reps]]*log_8[[#This Row],[Sets]],"") -> 245 | J19: Work like chest press
A20: 46228 | B20: 46228 | C20: Pec Fly Frontward | D20: 35 | E20: kg | F20: 5 | G20: 3 | H20: =IFERROR(log_8[[#This Row],[Reps]]*log_8[[#This Row],[Sets]],"") -> 15 | I20: =IFERROR(log_8[[#This Row],[Weight Value]]*log_8[[#This Row],[Reps]]*log_8[[#This Row],[Sets]],"") -> 525
A21: 46231 | B21: 46231 | C21: High Pully | D21: 40 | E21: kg | F21: 10 | G21: 3 | H21: =IFERROR(log_8[[#This Row],[Reps]]*log_8[[#This Row],[Sets]],"") -> 30 | I21: =IFERROR(log_8[[#This Row],[Weight Value]]*log_8[[#This Row],[Reps]]*log_8[[#This Row],[Sets]],"") -> 1200
A22: 46231 | B22: 46231 | C22: High Pully | D22: 40 | E22: kg | F22: 7 | G22: 1 | H22: =IFERROR(log_8[[#This Row],[Reps]]*log_8[[#This Row],[Sets]],"") -> 7 | I22: =IFERROR(log_8[[#This Row],[Weight Value]]*log_8[[#This Row],[Reps]]*log_8[[#This Row],[Sets]],"") -> 280
A23: 46231 | B23: 46231 | C23: Pec Fly Frontward | D23: 35 | E23: kg | F23: 10 | G23: 1 | H23: =IFERROR(log_8[[#This Row],[Reps]]*log_8[[#This Row],[Sets]],"") -> 10 | I23: =IFERROR(log_8[[#This Row],[Weight Value]]*log_8[[#This Row],[Reps]]*log_8[[#This Row],[Sets]],"") -> 350
A24: 46231 | B24: 46231 | C24: Pec Fly Frontward | D24: 35 | E24: kg | F24: 8 | G24: 2 | H24: =IFERROR(log_8[[#This Row],[Reps]]*log_8[[#This Row],[Sets]],"") -> 16 | I24: =IFERROR(log_8[[#This Row],[Weight Value]]*log_8[[#This Row],[Reps]]*log_8[[#This Row],[Sets]],"") -> 560
A25: 46231 | B25: 46231 | C25: Pec Fly Frontward | D25: 40 | E25: kg | F25: 5 | G25: 1 | H25: =IFERROR(log_8[[#This Row],[Reps]]*log_8[[#This Row],[Sets]],"") -> 5 | I25: =IFERROR(log_8[[#This Row],[Weight Value]]*log_8[[#This Row],[Reps]]*log_8[[#This Row],[Sets]],"") -> 200
A26: 46231 | B26: 46231 | C26: Pec Fly Backward | D26: 30 | E26: kg | F26: 8 | G26: 3 | H26: =IFERROR(log_8[[#This Row],[Reps]]*log_8[[#This Row],[Sets]],"") -> 24 | I26: =IFERROR(log_8[[#This Row],[Weight Value]]*log_8[[#This Row],[Reps]]*log_8[[#This Row],[Sets]],"") -> 720
A27: 46231 | B27: 46231 | C27: Incline Press | D27: 80 | E27: kg | F27: 10 | G27: 2 | H27: =IFERROR(log_8[[#This Row],[Reps]]*log_8[[#This Row],[Sets]],"") -> 20 | I27: =IFERROR(log_8[[#This Row],[Weight Value]]*log_8[[#This Row],[Reps]]*log_8[[#This Row],[Sets]],"") -> 1600
A28: 46231 | B28: 46231 | C28: Incline Press | D28: 80 | E28: kg | F28: 6 | G28: 1 | H28: =IFERROR(log_8[[#This Row],[Reps]]*log_8[[#This Row],[Sets]],"") -> 6 | I28: =IFERROR(log_8[[#This Row],[Weight Value]]*log_8[[#This Row],[Reps]]*log_8[[#This Row],[Sets]],"") -> 480
A29: 46231 | B29: 46231 | C29: Incline Press | D29: 80 | E29: kg | F29: 7 | G29: 1 | H29: =IFERROR(log_8[[#This Row],[Reps]]*log_8[[#This Row],[Sets]],"") -> 7 | I29: =IFERROR(log_8[[#This Row],[Weight Value]]*log_8[[#This Row],[Reps]]*log_8[[#This Row],[Sets]],"") -> 560
A30: 46231 | B30: 46231 | C30: Bicep Curl | D30: 7.5 | E30: kg | F30: 7 | G30: 1 | H30: =IFERROR(log_8[[#This Row],[Reps]]*log_8[[#This Row],[Sets]],"") -> 7 | I30: =IFERROR(log_8[[#This Row],[Weight Value]]*log_8[[#This Row],[Reps]]*log_8[[#This Row],[Sets]],"") -> 52.5
A31: 46231 | B31: 46231 | C31: Bicep Curl | D31: 7.5 | E31: kg | F31: 6 | G31: 3 | H31: =IFERROR(log_8[[#This Row],[Reps]]*log_8[[#This Row],[Sets]],"") -> 18 | I31: =IFERROR(log_8[[#This Row],[Weight Value]]*log_8[[#This Row],[Reps]]*log_8[[#This Row],[Sets]],"") -> 135
... A33: 46231 | B33: 46231 | C33: Rope Tricep Pressdown | D33: 25 | E33: kg | F33: 10 | G33: 1 | H33: =IFERROR(log_8[[#This Row],[Reps]]*log_8[[#This Row],[Sets]],"") -> 10 | I33: =IFERROR(log_8[[#This Row],[Weight Value]]*log_8[[#This Row],[Reps]]*log_8[[#This Row],[Sets]],"") -> 250
A34: 46231 | B34: 46231 | C34: Rope Tricep Pressdown | D34: 30 | E34: kg | F34: 5 | G34: 3 | H34: =IFERROR(log_8[[#This Row],[Reps]]*log_8[[#This Row],[Sets]],"") -> 15 | I34: =IFERROR(log_8[[#This Row],[Weight Value]]*log_8[[#This Row],[Reps]]*log_8[[#This Row],[Sets]],"") -> 450 | J34: reps - 6,5,4
A35: 46231 | B35: 46231 | C35: T Bar Row | D35: 15 | E35: kg | F35: 10 | G35: 2 | H35: =IFERROR(log_8[[#This Row],[Reps]]*log_8[[#This Row],[Sets]],"") -> 20 | I35: =IFERROR(log_8[[#This Row],[Weight Value]]*log_8[[#This Row],[Reps]]*log_8[[#This Row],[Sets]],"") -> 300
A36: 46231 | B36: 46231 | C36: T Bar Row | D36: 20 | E36: kg | F36: 8 | G36: 2 | H36: =IFERROR(log_8[[#This Row],[Reps]]*log_8[[#This Row],[Sets]],"") -> 16 | I36: =IFERROR(log_8[[#This Row],[Weight Value]]*log_8[[#This Row],[Reps]]*log_8[[#This Row],[Sets]],"") -> 320
H37: =IFERROR(log_8[[#This Row],[Reps]]*log_8[[#This Row],[Sets]],"") -> 0 | I37: =IFERROR(log_8[[#This Row],[Weight Value]]*log_8[[#This Row],[Reps]]*log_8[[#This Row],[Sets]],"") -> 0
H38: =IFERROR(log_8[[#This Row],[Reps]]*log_8[[#This Row],[Sets]],"") -> 0 | I38: =IFERROR(log_8[[#This Row],[Weight Value]]*log_8[[#This Row],[Reps]]*log_8[[#This Row],[Sets]],"") -> 0
H39: =IFERROR(log_8[[#This Row],[Reps]]*log_8[[#This Row],[Sets]],"") -> 0 | I39: =IFERROR(log_8[[#This Row],[Weight Value]]*log_8[[#This Row],[Reps]]*log_8[[#This Row],[Sets]],"") -> 0
H40: =IFERROR(log_8[[#This Row],[Reps]]*log_8[[#This Row],[Sets]],"") -> 0 | I40: =IFERROR(log_8[[#This Row],[Weight Value]]*log_8[[#This Row],[Reps]]*log_8[[#This Row],[Sets]],"") -> 0
H41: =IFERROR(log_8[[#This Row],[Reps]]*log_8[[#This Row],[Sets]],"") -> 0 | I41: =IFERROR(log_8[[#This Row],[Weight Value]]*log_8[[#This Row],[Reps]]*log_8[[#This Row],[Sets]],"") -> 0
...

Sheet Control
A1: Exercise | F1: Input | G1: = | H1: Output
A2: Seated Row | C2: Unit | E2: lbs | F2: 33 | H2: =ROUND(F2*0.45359237,0) -> 15 | I2: Kg
A3: Lat Pulldown | C3: kg | E3: kg | H3: =ROUND(F3/0.45359237,0) -> 0 | I3: lbs
A4: Chest Press | C4: lbs
A5: Leg Press
A6: Shoulder Press
A7: Bicep Curl
A8: Hammer Curl
A9: Rope Tricep Pressdown
A10: Sit Up
A11: Hex Press Negative
A12: Leg Extension
A13: Reverse Curl
A14: Pec Fly Backward
A15: Pec Fly Frontward
A16: Iso Lateral Row
... A21: Iso Lateral Chest Press
A32: internal calc - do not edit | B32: Attendance Log (edit Status here)
B33: Date | C33: Day | D33: Status
A34: =MATCH(Calendar!E3,Calendar!$N$1:$N$12,0) -> 8 | B34: 46023 | C34: =TEXT(B34,"ddd") -> Thu
A35: =DATE(Calendar!B3,A34,1) -> 46235 | B35: 46024 | C35: =TEXT(B35,"ddd") -> Fri
A36: =WEEKDAY(A35,1)-1 -> 6 | B36: 46025 | C36: =TEXT(B36,"ddd") -> Sat
B37: 46026 | C37: =TEXT(B37,"ddd") -> Sun
B38: 46027 | C38: =TEXT(B38,"ddd") -> Mon
B39: 46028 | C39: =TEXT(B39,"ddd") -> Tue
B40: 46029 | C40: =TEXT(B40,"ddd") -> Wed
B41: 46030 | C41: =TEXT(B41,"ddd") -> Thu
B42: 46031 | C42: =TEXT(B42,"ddd") -> Fri
B43: 46032 | C43: =TEXT(B43,"ddd") -> Sat
B44: 46033 | C44: =TEXT(B44,"ddd") -> Sun
B45: 46034 | C45: =TEXT(B45,"ddd") -> Mon
B46: 46035 | C46: =TEXT(B46,"ddd") -> Tue
B47: 46036 | C47: =TEXT(B47,"ddd") -> Wed
B48: 46037 | C48: =TEXT(B48,"ddd") -> Thu
... B170: 46160 | C170: =TEXT(B170,"ddd") -> Mon
B171: 46161 | C171: =TEXT(B171,"ddd") -> Tue | D171: Gym
B172: 46162 | C172: =TEXT(B172,"ddd") -> Wed
B173: 46163 | C173: =TEXT(B173,"ddd") -> Thu | D173: Gym
B174: 46164 | C174: =TEXT(B174,"ddd") -> Fri
B175: 46165 | C175: =TEXT(B175,"ddd") -> Sat
...

Sheet AIA Gym Log
A1: Date (DAY) | B1: Display Date | C1: Exercise | D1: Weight Value | E1: Unit | F1: Reps | G1: Sets | H1: Load | I1: Volumn | J1: Notes
A2: 46161 | B2: =TEXT(log[[#This Row],[Date (DAY)]],"dd MMM (ddd)") -> 19 May (Tue) | C2: Bicep Curl | D2: 6 | E2: kg | F2: 10 | G2: 3 | H2: =IFERROR(log[[#This Row],[Reps]]*log[[#This Row],[Sets]],"") -> 30 | I2: =IFERROR(log[[#This Row],[Weight Value]]*log[[#This Row],[Reps]]*log[[#This Row],[Sets]],"") -> 180 | J2: First gym session, weight is not recorded. only remember dumbell weight 6kg but suffer for left hand.
A3: 46161 | B3: =TEXT(log[[#This Row],[Date (DAY)]],"dd MMM (ddd)") -> 19 May (Tue) | C3: Leg Extension | D3: N/A | E3: N/A | F3: 10 | G3: 3 | I3: =IFERROR(log[[#This Row],[Weight Value]]*log[[#This Row],[Reps]]*log[[#This Row],[Sets]],"")
A4: 46161 | B4: =TEXT(log[[#This Row],[Date (DAY)]],"dd MMM (ddd)") -> 19 May (Tue) | C4: Chest Press | D4: N/A | E4: N/A | F4: 10 | G4: 3 | I4: =IFERROR(log[[#This Row],[Weight Value]]*log[[#This Row],[Reps]]*log[[#This Row],[Sets]],"")
A5: 46161 | B5: =TEXT(log[[#This Row],[Date (DAY)]],"dd MMM (ddd)") -> 19 May (Tue) | C5: Seated Row | D5: N/A | E5: N/A | F5: 10 | G5: 3 | I5: =IFERROR(log[[#This Row],[Weight Value]]*log[[#This Row],[Reps]]*log[[#This Row],[Sets]],"")
A6: 46161 | B6: =TEXT(log[[#This Row],[Date (DAY)]],"dd MMM (ddd)") -> 19 May (Tue) | C6: Lat Pulldown | D6: N/A | E6: N/A | F6: 10 | G6: 3 | I6: =IFERROR(log[[#This Row],[Weight Value]]*log[[#This Row],[Reps]]*log[[#This Row],[Sets]],"")
A7: 46161 | B7: =TEXT(log[[#This Row],[Date (DAY)]],"dd MMM (ddd)") -> 19 May (Tue) | C7: Shoulder Press | D7: N/A | E7: N/A | F7: 10 | G7: 3 | I7: =IFERROR(log[[#This Row],[Weight Value]]*log[[#This Row],[Reps]]*log[[#This Row],[Sets]],"")
A8: 46163 | B8: =TEXT(log[[#This Row],[Date (DAY)]],"dd MMM (ddd)") -> 21 May (Thu) | C8: Seated Row | D8: 30 | E8: lbs | F8: 10 | G8: 3 | H8: =IFERROR(log[[#This Row],[Reps]]*log[[#This Row],[Sets]],"") -> 30 | I8: =IFERROR(log[[#This Row],[Weight Value]]*log[[#This Row],[Reps]]*log[[#This Row],[Sets]],"") -> 900
A9: 46163 | B9: =TEXT(log[[#This Row],[Date (DAY)]],"dd MMM (ddd)") -> 21 May (Thu) | C9: Lat Pulldown | D9: 55 | E9: lbs | F9: 10 | G9: 3 | H9: =IFERROR(log[[#This Row],[Reps]]*log[[#This Row],[Sets]],"") -> 30 | I9: =IFERROR(log[[#This Row],[Weight Value]]*log[[#This Row],[Reps]]*log[[#This Row],[Sets]],"") -> 1650
A10: 46163 | B10: =TEXT(log[[#This Row],[Date (DAY)]],"dd MMM (ddd)") -> 21 May (Thu) | C10: Shoulder Press | D10: 20 | E10: lbs | F10: 10 | G10: 3 | H10: =IFERROR(log[[#This Row],[Reps]]*log[[#This Row],[Sets]],"") -> 30 | I10: =IFERROR(log[[#This Row],[Weight Value]]*log[[#This Row],[Reps]]*log[[#This Row],[Sets]],"") -> 600 | J10: Most difficult exercise
A11: 46163 | B11: =TEXT(log[[#This Row],[Date (DAY)]],"dd MMM (ddd)") -> 21 May (Thu) | C11: Chest Press | D11: 40 | E11: lbs | F11: 10 | G11: 3 | H11: =IFERROR(log[[#This Row],[Reps]]*log[[#This Row],[Sets]],"") -> 30 | I11: =IFERROR(log[[#This Row],[Weight Value]]*log[[#This Row],[Reps]]*log[[#This Row],[Sets]],"") -> 1200
A12: 46163 | B12: =TEXT(log[[#This Row],[Date (DAY)]],"dd MMM (ddd)") -> 21 May (Thu) | C12: Leg Press | D12: 165 | E12: lbs | F12: 10 | G12: 3 | H12: =IFERROR(log[[#This Row],[Reps]]*log[[#This Row],[Sets]],"") -> 30 | I12: =IFERROR(log[[#This Row],[Weight Value]]*log[[#This Row],[Reps]]*log[[#This Row],[Sets]],"") -> 4950
A13: 46163 | B13: =TEXT(log[[#This Row],[Date (DAY)]],"dd MMM (ddd)") -> 21 May (Thu) | C13: Rope Tricep Pressdown | D13: 17.5 | E13: lbs | F13: 10 | G13: 3 | H13: =IFERROR(log[[#This Row],[Reps]]*log[[#This Row],[Sets]],"") -> 30 | I13: =IFERROR(log[[#This Row],[Weight Value]]*log[[#This Row],[Reps]]*log[[#This Row],[Sets]],"") -> 525 | J13: Shoulder involvement noticed
A14: 46163 | B14: =TEXT(log[[#This Row],[Date (DAY)]],"dd MMM (ddd)") -> 21 May (Thu) | C14: Bicep Curl | D14: 6 | E14: kg | F14: 10 | G14: 3 | H14: =IFERROR(log[[#This Row],[Reps]]*log[[#This Row],[Sets]],"") -> 30 | I14: =IFERROR(log[[#This Row],[Weight Value]]*log[[#This Row],[Reps]]*log[[#This Row],[Sets]],"") -> 180 | J14: Left hand only 5 reps on 3rd set
A15: 46168 | B15: =TEXT(log[[#This Row],[Date (DAY)]],"dd MMM (ddd)") -> 26 May (Tue) | C15: Seated Row | D15: 40 | E15: lbs | F15: 10 | G15: 3 | H15: =IFERROR(log[[#This Row],[Reps]]*log[[#This Row],[Sets]],"") -> 30 | I15: =IFERROR(log[[#This Row],[Weight Value]]*log[[#This Row],[Reps]]*log[[#This Row],[Sets]],"") -> 1200
A16: 46168 | B16: =TEXT(log[[#This Row],[Date (DAY)]],"dd MMM (ddd)") -> 26 May (Tue) | C16: Lat Pulldown | D16: 60 | E16: lbs | F16: 10 | G16: 3 | H16: =IFERROR(log[[#This Row],[Reps]]*log[[#This Row],[Sets]],"") -> 30 | I16: =IFERROR(log[[#This Row],[Weight Value]]*log[[#This Row],[Reps]]*log[[#This Row],[Sets]],"") -> 1800
A17: 46168 | B17: =TEXT(log[[#This Row],[Date (DAY)]],"dd MMM (ddd)") -> 26 May (Tue) | C17: Chest Press | D17: 55 | E17: lbs | F17: 10 | G17: 3 | H17: =IFERROR(log[[#This Row],[Reps]]*log[[#This Row],[Sets]],"") -> 30 | I17: =IFERROR(log[[#This Row],[Weight Value]]*log[[#This Row],[Reps]]*log[[#This Row],[Sets]],"") -> 1650
A18: 46168 | B18: =TEXT(log[[#This Row],[Date (DAY)]],"dd MMM (ddd)") -> 26 May (Tue) | C18: Shoulder Press | D18: 20 | E18: lbs | F18: 6 | G18: 4 | H18: =IFERROR(log[[#This Row],[Reps]]*log[[#This Row],[Sets]],"") -> 24 | I18: =IFERROR(log[[#This Row],[Weight Value]]*log[[#This Row],[Reps]]*log[[#This Row],[Sets]],"") -> 480
A19: 46168 | B19: =TEXT(log[[#This Row],[Date (DAY)]],"dd MMM (ddd)") -> 26 May (Tue) | C19: Leg Press | D19: 165 | E19: lbs | F19: 14 | G19: 4 | H19: =IFERROR(log[[#This Row],[Reps]]*log[[#This Row],[Sets]],"") -> 56 | I19: =IFERROR(log[[#This Row],[Weight Value]]*log[[#This Row],[Reps]]*log[[#This Row],[Sets]],"") -> 9240
A20: 46168 | B20: =TEXT(log[[#This Row],[Date (DAY)]],"dd MMM (ddd)") -> 26 May (Tue) | C20: Rope Tricep Pressdown | D20: 12.5 | E20: lbs | F20: 10 | G20: 3 | H20: =IFERROR(log[[#This Row],[Reps]]*log[[#This Row],[Sets]],"") -> 30 | I20: =IFERROR(log[[#This Row],[Weight Value]]*log[[#This Row],[Reps]]*log[[#This Row],[Sets]],"") -> 375
A21: 46168 | B21: =TEXT(log[[#This Row],[Date (DAY)]],"dd MMM (ddd)") -> 26 May (Tue) | C21: Bicep Curl | D21: 4 | E21: kg | F21: 10 | G21: 4 | H21: =IFERROR(log[[#This Row],[Reps]]*log[[#This Row],[Sets]],"") -> 40 | I21: =IFERROR(log[[#This Row],[Weight Value]]*log[[#This Row],[Reps]]*log[[#This Row],[Sets]],"") -> 160
A22: 46168 | B22: =TEXT(log[[#This Row],[Date (DAY)]],"dd MMM (ddd)") -> 26 May (Tue) | C22: Leg Extension | D22: 35 | E22: lbs | F22: 8 | G22: 3 | H22: =IFERROR(log[[#This Row],[Reps]]*log[[#This Row],[Sets]],"") -> 24 | I22: =IFERROR(log[[#This Row],[Weight Value]]*log[[#This Row],[Reps]]*log[[#This Row],[Sets]],"") -> 840
A23: 46168 | B23: =TEXT(log[[#This Row],[Date (DAY)]],"dd MMM (ddd)") -> 26 May (Tue) | C23: Hex Press Negative | D23: 6 | E23: kg | F23: 6 | G23: 2 | H23: =IFERROR(log[[#This Row],[Reps]]*log[[#This Row],[Sets]],"") -> 12 | I23: =IFERROR(log[[#This Row],[Weight Value]]*log[[#This Row],[Reps]]*log[[#This Row],[Sets]],"") -> 72
A24: 46170 | B24: =TEXT(log[[#This Row],[Date (DAY)]],"dd MMM (ddd)") -> 28 May (Thu) | C24: Seated Row | D24: 45 | E24: lbs | F24: 10 | G24: 3 | H24: =IFERROR(log[[#This Row],[Reps]]*log[[#This Row],[Sets]],"") -> 30 | I24: =IFERROR(log[[#This Row],[Weight Value]]*log[[#This Row],[Reps]]*log[[#This Row],[Sets]],"") -> 1350
A25: 46170 | B25: =TEXT(log[[#This Row],[Date (DAY)]],"dd MMM (ddd)") -> 28 May (Thu) | C25: Lat Pulldown | D25: 65 | E25: lbs | F25: 10 | G25: 3 | H25: =IFERROR(log[[#This Row],[Reps]]*log[[#This Row],[Sets]],"") -> 30 | I25: =IFERROR(log[[#This Row],[Weight Value]]*log[[#This Row],[Reps]]*log[[#This Row],[Sets]],"") -> 1950
A26: 46170 | B26: =TEXT(log[[#This Row],[Date (DAY)]],"dd MMM (ddd)") -> 28 May (Thu) | C26: Chest Press | D26: 60 | E26: lbs | F26: 10 | G26: 3 | H26: =IFERROR(log[[#This Row],[Reps]]*log[[#This Row],[Sets]],"") -> 30 | I26: =IFERROR(log[[#This Row],[Weight Value]]*log[[#This Row],[Reps]]*log[[#This Row],[Sets]],"") -> 1800
... A33: 46170 | B33: =TEXT(log[[#This Row],[Date (DAY)]],"dd MMM (ddd)") -> 28 May (Thu) | C33: Rope Tricep Pressdown | D33: 12.5 | E33: lbs | F33: 12 | G33: 4 | H33: =IFERROR(log[[#This Row],[Reps]]*log[[#This Row],[Sets]],"") -> 48 | I33: =IFERROR(log[[#This Row],[Weight Value]]*log[[#This Row],[Reps]]*log[[#This Row],[Sets]],"") -> 600
A34: 46170 | B34: =TEXT(log[[#This Row],[Date (DAY)]],"dd MMM (ddd)") -> 28 May (Thu) | C34: Sit Up | D34: 50 | E34: kg | F34: 8 | G34: 2 | H34: =IFERROR(log[[#This Row],[Reps]]*log[[#This Row],[Sets]],"") -> 16 | I34: =IFERROR(log[[#This Row],[Weight Value]]*log[[#This Row],[Reps]]*log[[#This Row],[Sets]],"") -> 800 | J34: Bodyweight. Ab cramps during exercise, with sit-up bench full strech
A35: 46178 | B35: =TEXT(log[[#This Row],[Date (DAY)]],"dd MMM (ddd)") -> 05 Jun (Fri) | C35: Seated Row | D35: 45 | E35: lbs | F35: 10 | G35: 3 | H35: =IFERROR(log[[#This Row],[Reps]]*log[[#This Row],[Sets]],"") -> 30 | I35: =IFERROR(log[[#This Row],[Weight Value]]*log[[#This Row],[Reps]]*log[[#This Row],[Sets]],"") -> 1350 | J35: Cut activity, weight and reps. bcs still sick and next day competition. Start control breathing
A36: 46178 | B36: =TEXT(log[[#This Row],[Date (DAY)]],"dd MMM (ddd)") -> 05 Jun (Fri) | C36: Lat Pulldown | D36: 65 | E36: lbs | F36: 10 | G36: 3 | H36: =IFERROR(log[[#This Row],[Reps]]*log[[#This Row],[Sets]],"") -> 30 | I36: =IFERROR(log[[#This Row],[Weight Value]]*log[[#This Row],[Reps]]*log[[#This Row],[Sets]],"") -> 1950
A37: 46178 | B37: =TEXT(log[[#This Row],[Date (DAY)]],"dd MMM (ddd)") -> 05 Jun (Fri) | C37: Chest Press | D37: 32 | E37: kg | F37: 8 | G37: 3 | H37: =IFERROR(log[[#This Row],[Reps]]*log[[#This Row],[Sets]],"") -> 24 | I37: =IFERROR(log[[#This Row],[Weight Value]]*log[[#This Row],[Reps]]*log[[#This Row],[Sets]],"") -> 768
A38: 46178 | B38: =TEXT(log[[#This Row],[Date (DAY)]],"dd MMM (ddd)") -> 05 Jun (Fri) | C38: Shoulder Press | D38: 25 | E38: lbs | F38: 6 | G38: 3 | H38: =IFERROR(log[[#This Row],[Reps]]*log[[#This Row],[Sets]],"") -> 18 | I38: =IFERROR(log[[#This Row],[Weight Value]]*log[[#This Row],[Reps]]*log[[#This Row],[Sets]],"") -> 450
A39: 46178 | B39: =TEXT(log[[#This Row],[Date (DAY)]],"dd MMM (ddd)") -> 05 Jun (Fri) | C39: Leg Press | D39: 165 | E39: lbs | F39: 10 | G39: 3 | H39: =IFERROR(log[[#This Row],[Reps]]*log[[#This Row],[Sets]],"") -> 30 | I39: =IFERROR(log[[#This Row],[Weight Value]]*log[[#This Row],[Reps]]*log[[#This Row],[Sets]],"") -> 4950
A40: 46178 | B40: =TEXT(log[[#This Row],[Date (DAY)]],"dd MMM (ddd)") -> 05 Jun (Fri) | C40: Bicep Curl | D40: 4 | E40: kg | F40: 10 | G40: 3 | H40: =IFERROR(log[[#This Row],[Reps]]*log[[#This Row],[Sets]],"") -> 30 | I40: =IFERROR(log[[#This Row],[Weight Value]]*log[[#This Row],[Reps]]*log[[#This Row],[Sets]],"") -> 120
A41: 46178 | B41: =TEXT(log[[#This Row],[Date (DAY)]],"dd MMM (ddd)") -> 05 Jun (Fri) | C41: Hammer Curl | D41: 4 | E41: kg | F41: 10 | G41: 3 | H41: =IFERROR(log[[#This Row],[Reps]]*log[[#This Row],[Sets]],"") -> 30 | I41: =IFERROR(log[[#This Row],[Weight Value]]*log[[#This Row],[Reps]]*log[[#This Row],[Sets]],"") -> 120
A42: 46178 | B42: =TEXT(log[[#This Row],[Date (DAY)]],"dd MMM (ddd)") -> 05 Jun (Fri) | C42: Rope Tricep Pressdown | D42: 17.5 | E42: lbs | F42: 8 | G42: 3 | H42: =IFERROR(log[[#This Row],[Reps]]*log[[#This Row],[Sets]],"") -> 24 | I42: =IFERROR(log[[#This Row],[Weight Value]]*log[[#This Row],[Reps]]*log[[#This Row],[Sets]],"") -> 420
A43: 46182 | B43: =TEXT(log[[#This Row],[Date (DAY)]],"dd MMM (ddd)") -> 09 Jun (Tue) | C43: Seated Row | D43: 45 | E43: lbs | F43: 12 | G43: 3 | H43: =IFERROR(log[[#This Row],[Reps]]*log[[#This Row],[Sets]],"") -> 36 | I43: =IFERROR(log[[#This Row],[Weight Value]]*log[[#This Row],[Reps]]*log[[#This Row],[Sets]],"") -> 1620
A44: 46182 | B44: =TEXT(log[[#This Row],[Date (DAY)]],"dd MMM (ddd)") -> 09 Jun (Tue) | C44: Lat Pulldown | D44: 65 | E44: lbs | F44: 10 | G44: 3 | H44: =IFERROR(log[[#This Row],[Reps]]*log[[#This Row],[Sets]],"") -> 30 | I44: =IFERROR(log[[#This Row],[Weight Value]]*log[[#This Row],[Reps]]*log[[#This Row],[Sets]],"") -> 1950 | J44: start feel less pressure can up weight
A45: 46182 | B45: =TEXT(log[[#This Row],[Date (DAY)]],"dd MMM (ddd)") -> 09 Jun (Tue) | C45: Chest Press | D45: 32 | E45: kg | F45: 10 | G45: 3 | H45: =IFERROR(log[[#This Row],[Reps]]*log[[#This Row],[Sets]],"") -> 30 | I45: =IFERROR(log[[#This Row],[Weight Value]]*log[[#This Row],[Reps]]*log[[#This Row],[Sets]],"") -> 960
A46: 46182 | B46: =TEXT(log[[#This Row],[Date (DAY)]],"dd MMM (ddd)") -> 09 Jun (Tue) | C46: Leg Extension | D46: 35 | E46: kg | F46: 10 | G46: 3 | H46: =IFERROR(log[[#This Row],[Reps]]*log[[#This Row],[Sets]],"") -> 30 | I46: =IFERROR(log[[#This Row],[Weight Value]]*log[[#This Row],[Reps]]*log[[#This Row],[Sets]],"") -> 1050
...

Sheet Dashboard (AIA Data)
A1: Total Session = | B1: =ROWS(_xlfn.UNIQUE(log[Date (DAY)])) -> 15
A3: Row Labels | B3: Sum of Volumn
A4: 46161 | B4: 180
A5: 46163 | B5: 10005
A6: 46168 | B6: 15817
A7: 46170 | B7: 15420
A8: 46178 | B8: 10128
A9: 46182 | B9: 14285
A10: 46184 | B10: 13310
A11: 46189 | B11: 13860
A12: 46191 | B12: 15974
A13: 46196 | B13: 18806
A14: 46198 | B14: 21116.8
A15: 46202 | B15: 19285
... A18: 46212 | B18: 14952
A19: Grand Total | B19: 227226.8
A21: Row Labels | B21: Weight | C21: Load (Set*Rep)
A22: 46161 | B22: 6 | C22: 30
A23: 46163 | B23: 333.5 | C23: 210
A24: 46168 | B24: 397.5 | C24: 276
A25: 46170 | B25: 467 | C25: 350
A26: 46178 | B26: 357.5 | C26: 216
A27: 46182 | B27: 467.5 | C27: 317
A28: 46184 | B28: 432.5 | C28: 288
A29: 46189 | B29: 397.5 | C29: 308
A30: 46191 | B30: 459.6 | C30: 324
A31: 46196 | B31: 467.1 | C31: 373
A32: 46198 | B32: 481.1 | C32: 384
A33: 46202 | B33: 504 | C33: 332
... A36: 46212 | B36: 331.5 | C36: 368
A37: Grand Total | B37: 6175.3 | C37: 4536

Sheet Protein
A1: How much need:
A2: 1.6 - 2.2 g protein per kg
A3: If 60kg then need 120g protein/day
A5: Food | B5: Portion | C5: Protein
A6: Egg | B6: 1 | C6: 6g
A7: Milk | B7: 300 ml | C7: 8g
A8: Chicken | B8: 150g 200g | C8: 40-45g 50-55g
A9: Fish | B9: 150g 200g | C9: 30g 40g
A10: Banana | B10: 1 | C10: 1 - 1.5g
